Workbook

Sheet Donnees_SIG
A1: wkt_geom | B1: id | C1: area_m2 | D1: Type | E1: x | F1: y | G1: Pré-Classe | H1: Classe | I1: Conso | L1: =MAX(H:H) -> 80 | M1: =Classes_finales!$W$30*MAX(Classes_finales!D:D)^3+Classes_finales!$W$31*MAX(Classes_finales!D:D)^2+Classes_finales!$W$32*MAX(Classes_finales!D:D)+Classes_finales!$W$33 -> 7.9143 | P1: Zones
A2: Point (793509.03700621309690177 9639185.25444813817739487) | B2: 04e00000000000033e93 | C2: 14.9803 | D2: Habitation | E2: 793509.04 | F2: 9639185.3 | G2: =IF(C2="","",VLOOKUP(C2,Classes_detaillees!B:D,Classes_detaillees!C$1,TRUE)) -> 15 | H2: =IF(C2="","",VLOOKUP(C2,Classes_finales!B:D,Classes_finales!C$1,TRUE)) -> 15 | I2: =IF(E2="","",20) -> 20 | J2: =Classes_finales!$W$30*C2^3+Classes_finales!$W$31*C2^2+Classes_finales!$W$32*C2+Classes_finales!$W$33 -> 0.80114532 | K2: =IF(OR(C2<10,C2>450),0,IF(H2>=MAX(Classes_finales!D:D),$M$1,Donnees_SIG!J2)) -> 0.80114532 | P2: MURAMVYA
A3: Point (790084.54420316941104829 9637447.35277149081230164) | B3: 04e0000000000001e082 | C3: 70.122902 | D3: Habitation | E3: 790084.54 | F3: 9637447.4 | G3: =IF(C3="","",VLOOKUP(C3,Classes_detaillees!B:D,Classes_detaillees!C$1,TRUE)) -> 75 | H3: =IF(C3="","",VLOOKUP(C3,Classes_finales!B:D,Classes_finales!C$1,TRUE)) -> 80 | I3: =IF(E3="","",20) -> 20 | J3: =Classes_finales!$W$30*C3^3+Classes_finales!$W$31*C3^2+Classes_finales!$W$32*C3+Classes_finales!$W$33 -> 7.4339835 | K3: =IF(OR(C3<10,C3>450),0,IF(H3>=MAX(Classes_finales!D:D),$M$1,Donnees_SIG!J3)) -> 7.9143 | M3: =SUM(K:K) -> 33253.081 | P3: MURAMVYA
A4: Point (792076.61358734988607466 9638524.12234459258615971) | B4: 04e00000000000009948 | C4: 221.57899 | D4: Habitation | E4: 792076.61 | F4: 9638524.1 | G4: =IF(C4="","",VLOOKUP(C4,Classes_detaillees!B:D,Classes_detaillees!C$1,TRUE)) -> 225 | H4: =IF(C4="","",VLOOKUP(C4,Classes_finales!B:D,Classes_finales!C$1,TRUE)) -> 80 | I4: =IF(E4="","",20) -> 20 | J4: =Classes_finales!$W$30*C4^3+Classes_finales!$W$31*C4^2+Classes_finales!$W$32*C4+Classes_finales!$W$33 -> -97.434293 | K4: =IF(OR(C4<10,C4>450),0,IF(H4>=MAX(Classes_finales!D:D),$M$1,Donnees_SIG!J4)) -> 7.9143 | P4: MURAMVYA
A5: Point (793530.52964762528426945 9639368.63834058120846748) | B5: 04e0000000000003ec2f | C5: 90.600601 | D5: Habitation | E5: 793530.53 | F5: 9639368.6 | G5: =IF(C5="","",VLOOKUP(C5,Classes_detaillees!B:D,Classes_detaillees!C$1,TRUE)) -> 95 | H5: =IF(C5="","",VLOOKUP(C5,Classes_finales!B:D,Classes_finales!C$1,TRUE)) -> 80 | I5: =IF(E5="","",20) -> 20 | J5: =Classes_finales!$W$30*C5^3+Classes_finales!$W$31*C5^2+Classes_finales!$W$32*C5+Classes_finales!$W$33 -> 7.8622615 | K5: =IF(OR(C5<10,C5>450),0,IF(H5>=MAX(Classes_finales!D:D),$M$1,Donnees_SIG!J5)) -> 7.9143 | P5: MURAMVYA
A6: Point (791582.7869591626804322 9638412.57075314223766327) | B6: 04e000000000000804f7 | C6: 77.040199 | D6: Habitation | E6: 791582.79 | F6: 9638412.6 | G6: =IF(C6="","",VLOOKUP(C6,Classes_detaillees!B:D,Classes_detaillees!C$1,TRUE)) -> 80 | H6: =IF(C6="","",VLOOKUP(C6,Classes_finales!B:D,Classes_finales!C$1,TRUE)) -> 80 | I6: =IF(E6="","",20) -> 20 | J6: =Classes_finales!$W$30*C6^3+Classes_finales!$W$31*C6^2+Classes_finales!$W$32*C6+Classes_finales!$W$33 -> 7.8183425 | K6: =IF(OR(C6<10,C6>450),0,IF(H6>=MAX(Classes_finales!D:D),$M$1,Donnees_SIG!J6)) -> 7.9143 | P6: MURAMVYA
A7: Point (791860.25560740660876036 9639478.49120753258466721) | B7: 04e00000000000036bb9 | C7: 133.35519 | D7: Habitation | E7: 791860.26 | F7: 9639478.5 | G7: =IF(C7="","",VLOOKUP(C7,Classes_detaillees!B:D,Classes_detaillees!C$1,TRUE)) -> 135 | H7: =IF(C7="","",VLOOKUP(C7,Classes_finales!B:D,Classes_finales!C$1,TRUE)) -> 80 | I7: =IF(E7="","",20) -> 20 | J7: =Classes_finales!$W$30*C7^3+Classes_finales!$W$31*C7^2+Classes_finales!$W$32*C7+Classes_finales!$W$33 -> -1.1965817 | K7: =IF(OR(C7<10,C7>450),0,IF(H7>=MAX(Classes_finales!D:D),$M$1,Donnees_SIG!J7)) -> 7.9143 | P7: MURAMVYA
A8: Point (792444.34041615366004407 9638649.87919917143881321) | B8: 04e0000000000008d545 | C8: 35.451199 | D8: Habitation | E8: 792444.34 | F8: 9638649.9 | G8: =IF(C8="","",VLOOKUP(C8,Classes_detaillees!B:D,Classes_detaillees!C$1,TRUE)) -> 40 | H8: =IF(C8="","",VLOOKUP(C8,Classes_finales!B:D,Classes_finales!C$1,TRUE)) -> 40 | I8: =IF(E8="","",20) -> 20 | J8: =Classes_finales!$W$30*C8^3+Classes_finales!$W$31*C8^2+Classes_finales!$W$32*C8+Classes_finales!$W$33 -> 3.4133132 | K8: =IF(OR(C8<10,C8>450),0,IF(H8>=MAX(Classes_finales!D:D),$M$1,Donnees_SIG!J8)) -> 3.4133132 | P8: MURAMVYA
A9: Point (790540.97151674632914364 9637824.88431598618626595) | B9: 04e0000000000000f993 | C9: 138.2466 | D9: Habitation | E9: 790540.97 | F9: 9637824.9 | G9: =IF(C9="","",VLOOKUP(C9,Classes_detaillees!B:D,Classes_detaillees!C$1,TRUE)) -> 140 | H9: =IF(C9="","",VLOOKUP(C9,Classes_finales!B:D,Classes_finales!C$1,TRUE)) -> 80 | I9: =IF(E9="","",20) -> 20 | J9: =Classes_finales!$W$30*C9^3+Classes_finales!$W$31*C9^2+Classes_finales!$W$32*C9+Classes_finales!$W$33 -> -3.4085167 | K9: =IF(OR(C9<10,C9>450),0,IF(H9>=MAX(Classes_finales!D:D),$M$1,Donnees_SIG!J9)) -> 7.9143 | P9: MURAMVYA
A10: Point (792751.64322436752263457 9638942.24993075989186764) | B10: 04e00000000000035ff0 | C10: 244.83279 | D10: Habitation | E10: 792751.64 | F10: 9638942.2 | G10: =IF(C10="","",VLOOKUP(C10,Classes_detaillees!B:D,Classes_detaillees!C$1,TRUE)) -> 245 | H10: =IF(C10="","",VLOOKUP(C10,Classes_finales!B:D,Classes_finales!C$1,TRUE)) -> 80 | I10: =IF(E10="","",20) -> 20 | J10: =Classes_finales!$W$30*C10^3+Classes_finales!$W$31*C10^2+Classes_finales!$W$32*C10+Classes_finales!$W$33 -> -148.19262 | K10: =IF(OR(C10<10,C10>450),0,IF(H10>=MAX(Classes_finales!D:D),$M$1,Donnees_SIG!J10)) -> 7.9143 | P10: MURAMVYA
A11: Point (789779.14874355203937739 9637349.99885953217744827) | B11: 04e000000000000143ea | C11: 86.8946 | D11: Habitation | E11: 789779.15 | F11: 9637350 | G11: =IF(C11="","",VLOOKUP(C11,Classes_detaillees!B:D,Classes_detaillees!C$1,TRUE)) -> 90 | H11: =IF(C11="","",VLOOKUP(C11,Classes_finales!B:D,Classes_finales!C$1,TRUE)) -> 80 | I11: =IF(E11="","",20) -> 20 | J11: =Classes_finales!$W$30*C11^3+Classes_finales!$W$31*C11^2+Classes_finales!$W$32*C11+Classes_finales!$W$33 -> 7.9558285 | K11: =IF(OR(C11<10,C11>450),0,IF(H11>=MAX(Classes_finales!D:D),$M$1,Donnees_SIG!J11)) -> 7.9143 | P11: MURAMVYA
A12: Point (790619.82252183568198234 9638199.67660908028483391) | B12: 04e000000000000053e0 | C12: 86.124496 | D12: Habitation | E12: 790619.82 | F12: 9638199.7 | G12: =IF(C12="","",VLOOKUP(C12,Classes_detaillees!B:D,Classes_detaillees!C$1,TRUE)) -> 90 | H12: =IF(C12="","",VLOOKUP(C12,Classes_finales!B:D,Classes_finales!C$1,TRUE)) -> 80 | I12: =IF(E12="","",20) -> 20 | J12: =Classes_finales!$W$30*C12^3+Classes_finales!$W$31*C12^2+Classes_finales!$W$32*C12+Classes_finales!$W$33 -> 7.9646808 | K12: =IF(OR(C12<10,C12>450),0,IF(H12>=MAX(Classes_finales!D:D),$M$1,Donnees_SIG!J12)) -> 7.9143 | P12: MURAMVYA
A13: Point (790624.4120712666772306 9638159.12023354880511761) | B13: 04e000000000000a229c | C13: 22.028799 | D13: Habitation | E13: 790624.41 | F13: 9638159.1 | G13: =IF(C13="","",VLOOKUP(C13,Classes_detaillees!B:D,Classes_detaillees!C$1,TRUE)) -> 25 | H13: =IF(C13="","",VLOOKUP(C13,Classes_finales!B:D,Classes_finales!C$1,TRUE)) -> 30 | I13: =IF(E13="","",20) -> 20 | J13: =Classes_finales!$W$30*C13^3+Classes_finales!$W$31*C13^2+Classes_finales!$W$32*C13+Classes_finales!$W$33 -> 1.6295308 | K13: =IF(OR(C13<10,C13>450),0,IF(H13>=MAX(Classes_finales!D:D),$M$1,Donnees_SIG!J13)) -> 1.6295308 | P13: MURAMVYA
A14: Point (790904.10472455434501171 9638252.34568655863404274) | B14: 04e0000000000004a3b4 | C14: 111.862 | D14: Habitation | E14: 790904.1 | F14: 9638252.3 | G14: =IF(C14="","",VLOOKUP(C14,Classes_detaillees!B:D,Classes_detaillees!C$1,TRUE)) -> 115 | H14: =IF(C14="","",VLOOKUP(C14,Classes_finales!B:D,Classes_finales!C$1,TRUE)) -> 80 | I14: =IF(E14="","",20) -> 20 | J14: =Classes_finales!$W$30*C14^3+Classes_finales!$W$31*C14^2+Classes_finales!$W$32*C14+Classes_finales!$W$33 -> 5.4212598 | K14: =IF(OR(C14<10,C14>450),0,IF(H14>=MAX(Classes_finales!D:D),$M$1,Donnees_SIG!J14)) -> 7.9143 | P14: MURAMVYA
A15: Point (790518.41982515784911811 9639614.79569894261658192) | B15: 04e0000000000007d195 | C15: 83.108902 | D15: Habitation | E15: 790518.42 | F15: 9639614.8 | G15: =IF(C15="","",VLOOKUP(C15,Classes_detaillees!B:D,Classes_detaillees!C$1,TRUE)) -> 85 | H15: =IF(C15="","",VLOOKUP(C15,Classes_finales!B:D,Classes_finales!C$1,TRUE)) -> 80 | I15: =IF(E15="","",20) -> 20 | J15: =Classes_finales!$W$30*C15^3+Classes_finales!$W$31*C15^2+Classes_finales!$W$32*C15+Classes_finales!$W$33 -> 7.965981 | K15: =IF(OR(C15<10,C15>450),0,IF(H15>=MAX(Classes_finales!D:D),$M$1,Donnees_SIG!J15)) -> 7.9143 | P15: MURAMVYA
... A151: Point (792049.68066457519307733 9638724.96513939462602139) | B151: 04e000000000000a0de5 | C151: 126.7044 | D151: Habitation | E151: 792049.68 | F151: 9638725 | G151: =IF(C151="","",VLOOKUP(C151,Classes_detaillees!B:D,Classes_detaillees!C$1,TRUE)) -> 130 | H151: =IF(C151="","",VLOOKUP(C151,Classes_finales!B:D,Classes_finales!C$1,TRUE)) -> 80 | I151: =IF(E151="","",20) -> 20 | J151: =Classes_finales!$W$30*C151^3+Classes_finales!$W$31*C151^2+Classes_finales!$W$32*C151+Classes_finales!$W$33 -> 1.3683303 | K151: =IF(OR(C151<10,C151>450),0,IF(H151>=MAX(Classes_finales!D:D),$M$1,Donnees_SIG!J151)) -> 7.9143 | P151: MURAMVYA
A152: Point (792957.35292386589571834 9639200.24041246250271797) | B152: 4e+211 | C152: 65.113098 | D152: Habitation | E152: 792957.35 | F152: 9639200.2 | G152: =IF(C152="","",VLOOKUP(C152,Classes_detaillees!B:D,Classes_detaillees!C$1,TRUE)) -> 70 | H152: =IF(C152="","",VLOOKUP(C152,Classes_finales!B:D,Classes_finales!C$1,TRUE)) -> 70 | I152: =IF(E152="","",20) -> 20 | J152: =Classes_finales!$W$30*C152^3+Classes_finales!$W$31*C152^2+Classes_finales!$W$32*C152+Classes_finales!$W$33 -> 7.0333892 | K152: =IF(OR(C152<10,C152>450),0,IF(H152>=MAX(Classes_finales!D:D),$M$1,Donnees_SIG!J152)) -> 7.0333892 | P152: MURAMVYA
A153: Point (790702.9098748592659831 9638054.92456855066120625) | B153: 04e00000000000056efa | C153: 109.5338 | D153: Habitation | E153: 790702.91 | F153: 9638054.9 | G153: =IF(C153="","",VLOOKUP(C153,Classes_detaillees!B:D,Classes_detaillees!C$1,TRUE)) -> 110 | H153: =IF(C153="","",VLOOKUP(C153,Classes_finales!B:D,Classes_finales!C$1,TRUE)) -> 80 | I153: =IF(E153="","",20) -> 20 | J153: =Classes_finales!$W$30*C153^3+Classes_finales!$W$31*C153^2+Classes_finales!$W$32*C153+Classes_finales!$W$33 -> 5.8666397 | K153: =IF(OR(C153<10,C153>450),0,IF(H153>=MAX(Classes_finales!D:D),$M$1,Donnees_SIG!J153)) -> 7.9143 | P153: MURAMVYA
A154: Point (790290.99578551016747952 9637407.06889744289219379) | B154: 04e00000000000070fb7 | C154: 91.342102 | D154: Habitation | E154: 790291 | F154: 9637407.1 | G154: =IF(C154="","",VLOOKUP(C154,Classes_detaillees!B:D,Classes_detaillees!C$1,TRUE)) -> 95 | H154: =IF(C154="","",VLOOKUP(C154,Classes_finales!B:D,Classes_finales!C$1,TRUE)) -> 80 | I154: =IF(E154="","",20) -> 20 | J154: =Classes_finales!$W$30*C154^3+Classes_finales!$W$31*C154^2+Classes_finales!$W$32*C154+Classes_finales!$W$33 -> 7.8330641 | K154: =IF(OR(C154<10,C154>450),0,IF(H154>=MAX(Classes_finales!D:D),$M$1,Donnees_SIG!J154)) -> 7.9143 | P154: MURAMVYA
A155: Point (790635.80865912977606058 9638178.73042945377528667) | B155: 04e000000000000a2969 | C155: 55.143101 | D155: Habitation | E155: 790635.81 | F155: 9638178.7 | G155: =IF(C155="","",VLOOKUP(C155,Classes_detaillees!B:D,Classes_detaillees!C$1,TRUE)) -> 60 | H155: =IF(C155="","",VLOOKUP(C155,Classes_finales!B:D,Classes_finales!C$1,TRUE)) -> 60 | I155: =IF(E155="","",20) -> 20 | J155: =Classes_finales!$W$30*C155^3+Classes_finales!$W$31*C155^2+Classes_finales!$W$32*C155+Classes_finales!$W$33 -> 5.9960774 | K155: =IF(OR(C155<10,C155>450),0,IF(H155>=MAX(Classes_finales!D:D),$M$1,Donnees_SIG!J155)) -> 5.9960774 | P155: MURAMVYA
A156: Point (790439.92310318944510072 9637995.89375820942223072) | B156: 04e00000000000066ddb | C156: 97.776199 | D156: Habitation | E156: 790439.92 | F156: 9637995.9 | G156: =IF(C156="","",VLOOKUP(C156,Classes_detaillees!B:D,Classes_detaillees!C$1,TRUE)) -> 100 | H156: =IF(C156="","",VLOOKUP(C156,Classes_finales!B:D,Classes_finales!C$1,TRUE)) -> 80 | I156: =IF(E156="","",20) -> 20 | J156: =Classes_finales!$W$30*C156^3+Classes_finales!$W$31*C156^2+Classes_finales!$W$32*C156+Classes_finales!$W$33 -> 7.4230017 | K156: =IF(OR(C156<10,C156>450),0,IF(H156>=MAX(Classes_finales!D:D),$M$1,Donnees_SIG!J156)) -> 7.9143 | P156: MURAMVYA
A157: Point (792023.95589159382507205 9638401.39724837243556976) | B157: 04e00000000000097147 | C157: 432.29129 | D157: Habitation | E157: 792023.96 | F157: 9638401.4 | G157: =IF(C157="","",VLOOKUP(C157,Classes_detaillees!B:D,Classes_detaillees!C$1,TRUE)) -> 435 | H157: =IF(C157="","",VLOOKUP(C157,Classes_finales!B:D,Classes_finales!C$1,TRUE)) -> 80 | I157: =IF(E157="","",20) -> 20 | J157: =Classes_finales!$W$30*C157^3+Classes_finales!$W$31*C157^2+Classes_finales!$W$32*C157+Classes_finales!$W$33 -> -1180.4489 | K157: =IF(OR(C157<10,C157>450),0,IF(H157>=MAX(Classes_finales!D:D),$M$1,Donnees_SIG!J157)) -> 7.9143 | P157: MURAMVYA
A158: Point (783071.79879270470701158 9635719.94467675685882568) | B158: 04e0000000000006abd9 | C158: 28.4277 | D158: Habitation | E158: 783071.8 | F158: 9635719.9 | G158: =IF(C158="","",VLOOKUP(C158,Classes_detaillees!B:D,Classes_detaillees!C$1,TRUE)) -> 30 | H158: =IF(C158="","",VLOOKUP(C158,Classes_finales!B:D,Classes_finales!C$1,TRUE)) -> 30 | I158: =IF(E158="","",20) -> 20 | J158: =Classes_finales!$W$30*C158^3+Classes_finales!$W$31*C158^2+Classes_finales!$W$32*C158+Classes_finales!$W$33 -> 2.4582633 | K158: =IF(OR(C158<10,C158>450),0,IF(H158>=MAX(Classes_finales!D:D),$M$1,Donnees_SIG!J158)) -> 2.4582633 | P158: MURAMVYA
A159: Point (791997.54937996913213283 9638569.11416959390044212) | B159: 04e0000000000008baa2 | C159: 47.922699 | D159: Habitation | E159: 791997.55 | F159: 9638569.1 | G159: =IF(C159="","",VLOOKUP(C159,Classes_detaillees!B:D,Classes_detaillees!C$1,TRUE)) -> 50 | H159: =IF(C159="","",VLOOKUP(C159,Classes_finales!B:D,Classes_finales!C$1,TRUE)) -> 50 | I159: =IF(E159="","",20) -> 20 | J159: =Classes_finales!$W$30*C159^3+Classes_finales!$W$31*C159^2+Classes_finales!$W$32*C159+Classes_finales!$W$33 -> 5.1004176 | K159: =IF(OR(C159<10,C159>450),0,IF(H159>=MAX(Classes_finales!D:D),$M$1,Donnees_SIG!J159)) -> 5.1004176 | P159: MURAMVYA
A160: Point (783409.79789347131736577 9637043.61674897931516171) | B160: 04e00000000000092444 | C160: 78.0504 | D160: Habitation | E160: 783409.8 | F160: 9637043.6 | G160: =IF(C160="","",VLOOKUP(C160,Classes_detaillees!B:D,Classes_detaillees!C$1,TRUE)) -> 80 | H160: =IF(C160="","",VLOOKUP(C160,Classes_finales!B:D,Classes_finales!C$1,TRUE)) -> 80 | I160: =IF(E160="","",20) -> 20 | J160: =Classes_finales!$W$30*C160^3+Classes_finales!$W$31*C160^2+Classes_finales!$W$32*C160+Classes_finales!$W$33 -> 7.8560207 | K160: =IF(OR(C160<10,C160>450),0,IF(H160>=MAX(Classes_finales!D:D),$M$1,Donnees_SIG!J160)) -> 7.9143 | P160: MURAMVYA
A161: Point (791987.04002950899302959 9639701.98860803432762623) | B161: 04e00000000000026213 | C161: 75.487503 | D161: Habitation | E161: 791987.04 | F161: 9639702 | G161: =IF(C161="","",VLOOKUP(C161,Classes_detaillees!B:D,Classes_detaillees!C$1,TRUE)) -> 80 | H161: =IF(C161="","",VLOOKUP(C161,Classes_finales!B:D,Classes_finales!C$1,TRUE)) -> 80 | I161: =IF(E161="","",20) -> 20 | J161: =Classes_finales!$W$30*C161^3+Classes_finales!$W$31*C161^2+Classes_finales!$W$32*C161+Classes_finales!$W$33 -> 7.7508337 | K161: =IF(OR(C161<10,C161>450),0,IF(H161>=MAX(Classes_finales!D:D),$M$1,Donnees_SIG!J161)) -> 7.9143 | P161: MURAMVYA
A162: Point (790903.19787352648563683 9638171.50759093835949898) | B162: 04e000000000000352ee | C162: 50.679501 | D162: Habitation | E162: 790903.2 | F162: 9638171.5 | G162: =IF(C162="","",VLOOKUP(C162,Classes_detaillees!B:D,Classes_detaillees!C$1,TRUE)) -> 55 | H162: =IF(C162="","",VLOOKUP(C162,Classes_finales!B:D,Classes_finales!C$1,TRUE)) -> 60 | I162: =IF(E162="","",20) -> 20 | J162: =Classes_finales!$W$30*C162^3+Classes_finales!$W$31*C162^2+Classes_finales!$W$32*C162+Classes_finales!$W$33 -> 5.453153 | K162: =IF(OR(C162<10,C162>450),0,IF(H162>=MAX(Classes_finales!D:D),$M$1,Donnees_SIG!J162)) -> 5.453153 | P162: MURAMVYA
A163: Point (783180.41659958916716278 9636401.56933924928307533) | B163: 04e0000000000004d568 | C163: 81.0084 | D163: Habitation | E163: 783180.42 | F163: 9636401.6 | G163: =IF(C163="","",VLOOKUP(C163,Classes_detaillees!B:D,Classes_detaillees!C$1,TRUE)) -> 85 | H163: =IF(C163="","",VLOOKUP(C163,Classes_finales!B:D,Classes_finales!C$1,TRUE)) -> 80 | I163: =IF(E163="","",20) -> 20 | J163: =Classes_finales!$W$30*C163^3+Classes_finales!$W$31*C163^2+Classes_finales!$W$32*C163+Classes_finales!$W$33 -> 7.9367448 | K163: =IF(OR(C163<10,C163>450),0,IF(H163>=MAX(Classes_finales!D:D),$M$1,Donnees_SIG!J163)) -> 7.9143 | P163: MURAMVYA
A164: Point (791389.83023138158023357 9638389.40355021879076958) | B164: 04e0000000000005c592 | C164: 148.9818 | D164: Habitation | E164: 791389.83 | F164: 9638389.4 | G164: =IF(C164="","",VLOOKUP(C164,Classes_detaillees!B:D,Classes_detaillees!C$1,TRUE)) -> 150 | H164: =IF(C164="","",VLOOKUP(C164,Classes_finales!B:D,Classes_finales!C$1,TRUE)) -> 80 | I164: =IF(E164="","",20) -> 20 | J164: =Classes_finales!$W$30*C164^3+Classes_finales!$W$31*C164^2+Classes_finales!$W$32*C164+Classes_finales!$W$33 -> -9.3051039 | K164: =IF(OR(C164<10,C164>450),0,IF(H164>=MAX(Classes_finales!D:D),$M$1,Donnees_SIG!J164)) -> 7.9143 | P164: MURAMVYA
... A3466: Point (791461.61513671395368874 9638420.19641479104757309) | B3466: 04e0000000000007f7aa | C3466: 95.384003 | D3466: Habitation | E3466: 791461.62 | F3466: 9638420.2 | G3466: =IF(C3466="","",VLOOKUP(C3466,Classes_detaillees!B:D,Classes_detaillees!C$1,TRUE)) -> 100 | H3466: =IF(C3466="","",VLOOKUP(C3466,Classes_finales!B:D,Classes_finales!C$1,TRUE)) -> 80 | I3466: =IF(E3466="","",20) -> 20 | J3466: =Classes_finales!$W$30*C3466^3+Classes_finales!$W$31*C3466^2+Classes_finales!$W$32*C3466+Classes_finales!$W$33 -> 7.6092082 | K3466: =IF(OR(C3466<10,C3466>450),0,IF(H3466>=MAX(Classes_finales!D:D),$M$1,Donnees_SIG!J3466)) -> 7.9143 | P3466: MURAMVYA
A3467: Point (790020.6511854943819344 9637740.53042383678257465) | B3467: 4e+151 | C3467: 37.145599 | D3467: Habitation | E3467: 790020.65 | F3467: 9637740.5 | G3467: =IF(C3467="","",VLOOKUP(C3467,Classes_detaillees!B:D,Classes_detaillees!C$1,TRUE)) -> 40 | H3467: =IF(C3467="","",VLOOKUP(C3467,Classes_finales!B:D,Classes_finales!C$1,TRUE)) -> 40 | I3467: =IF(E3467="","",20) -> 20 | J3467: =Classes_finales!$W$30*C3467^3+Classes_finales!$W$31*C3467^2+Classes_finales!$W$32*C3467+Classes_finales!$W$33 -> 3.6463682 | K3467: =IF(OR(C3467<10,C3467>450),0,IF(H3467>=MAX(Classes_finales!D:D),$M$1,Donnees_SIG!J3467)) -> 3.6463682 | P3467: MURAMVYA
A3468: Point (792442.98523083375766873 9638484.88669457286596298) | B3468: 04e0000000000001c204 | C3468: 68.233299 | D3468: Habitation | E3468: 792442.99 | F3468: 9638484.9 | G3468: =IF(C3468="","",VLOOKUP(C3468,Classes_detaillees!B:D,Classes_detaillees!C$1,TRUE)) -> 70 | H3468: =IF(C3468="","",VLOOKUP(C3468,Classes_finales!B:D,Classes_finales!C$1,TRUE)) -> 70 | I3468: =IF(E3468="","",20) -> 20 | J3468: =Classes_finales!$W$30*C3468^3+Classes_finales!$W$31*C3468^2+Classes_finales!$W$32*C3468+Classes_finales!$W$33 -> 7.2939087 | K3468: =IF(OR(C3468<10,C3468>450),0,IF(H3468>=MAX(Classes_finales!D:D),$M$1,Donnees_SIG!J3468)) -> 7.2939087 | P3468: MURAMVYA
A3469: Point (782993.52104442031122744 9635836.17669246345758438) | B3469: 04e00000000000087cc2 | C3469: 173.3334 | D3469: Habitation | E3469: 782993.52 | F3469: 9635836.2 | G3469: =IF(C3469="","",VLOOKUP(C3469,Classes_detaillees!B:D,Classes_detaillees!C$1,TRUE)) -> 175 | H3469: =IF(C3469="","",VLOOKUP(C3469,Classes_finales!B:D,Classes_finales!C$1,TRUE)) -> 80 | I3469: =IF(E3469="","",20) -> 20 | J3469: =Classes_finales!$W$30*C3469^3+Classes_finales!$W$31*C3469^2+Classes_finales!$W$32*C3469+Classes_finales!$W$33 -> -28.6714 | K3469: =IF(OR(C3469<10,C3469>450),0,IF(H3469>=MAX(Classes_finales!D:D),$M$1,Donnees_SIG!J3469)) -> 7.9143 | P3469: MURAMVYA
A3470: Point (790550.43419497681315988 9638145.19059307314455509) | B3470: 04e000000000000489ce | C3470: 40.5863 | D3470: Habitation | E3470: 790550.43 | F3470: 9638145.2 | G3470: =IF(C3470="","",VLOOKUP(C3470,Classes_detaillees!B:D,Classes_detaillees!C$1,TRUE)) -> 45 | H3470: =IF(C3470="","",VLOOKUP(C3470,Classes_finales!B:D,Classes_finales!C$1,TRUE)) -> 50 | I3470: =IF(E3470="","",20) -> 20 | J3470: =Classes_finales!$W$30*C3470^3+Classes_finales!$W$31*C3470^2+Classes_finales!$W$32*C3470+Classes_finales!$W$33 -> 4.1184917 | K3470: =IF(OR(C3470<10,C3470>450),0,IF(H3470>=MAX(Classes_finales!D:D),$M$1,Donnees_SIG!J3470)) -> 4.1184917 | P3470: MURAMVYA
A3471: Point (782745.75447408470790833 9635803.55804910883307457) | B3471: 04e00000000000060862 | C3471: 43.949299 | D3471: Habitation | E3471: 782745.75 | F3471: 9635803.6 | G3471: =IF(C3471="","",VLOOKUP(C3471,Classes_detaillees!B:D,Classes_detaillees!C$1,TRUE)) -> 45 | H3471: =IF(C3471="","",VLOOKUP(C3471,Classes_finales!B:D,Classes_finales!C$1,TRUE)) -> 50 | I3471: =IF(E3471="","",20) -> 20 | J3471: =Classes_finales!$W$30*C3471^3+Classes_finales!$W$31*C3471^2+Classes_finales!$W$32*C3471+Classes_finales!$W$33 -> 4.5746077 | K3471: =IF(OR(C3471<10,C3471>450),0,IF(H3471>=MAX(Classes_finales!D:D),$M$1,Donnees_SIG!J3471)) -> 4.5746077 | P3471: MURAMVYA
A3472: Point (782995.87593182525597513 9636244.85094748437404633) | B3472: 04e00000000000045b6b | C3472: 59.490101 | D3472: Habitation | E3472: 782995.88 | F3472: 9636244.9 | G3472: =IF(C3472="","",VLOOKUP(C3472,Classes_detaillees!B:D,Classes_detaillees!C$1,TRUE)) -> 60 | H3472: =IF(C3472="","",VLOOKUP(C3472,Classes_finales!B:D,Classes_finales!C$1,TRUE)) -> 60 | I3472: =IF(E3472="","",20) -> 20 | J3472: =Classes_finales!$W$30*C3472^3+Classes_finales!$W$31*C3472^2+Classes_finales!$W$32*C3472+Classes_finales!$W$33 -> 6.4824502 | K3472: =IF(OR(C3472<10,C3472>450),0,IF(H3472>=MAX(Classes_finales!D:D),$M$1,Donnees_SIG!J3472)) -> 6.4824502 | P3472: MURAMVYA
A3473: Point (791728.71731246635317802 9638537.91460727155208588) | B3473: 04e000000000000493fc | C3473: 157.21021 | D3473: Habitation | E3473: 791728.72 | F3473: 9638537.9 | G3473: =IF(C3473="","",VLOOKUP(C3473,Classes_detaillees!B:D,Classes_detaillees!C$1,TRUE)) -> 160 | H3473: =IF(C3473="","",VLOOKUP(C3473,Classes_finales!B:D,Classes_finales!C$1,TRUE)) -> 80 | I3473: =IF(E3473="","",20) -> 20 | J3473: =Classes_finales!$W$30*C3473^3+Classes_finales!$W$31*C3473^2+Classes_finales!$W$32*C3473+Classes_finales!$W$33 -> -14.86849 | K3473: =IF(OR(C3473<10,C3473>450),0,IF(H3473>=MAX(Classes_finales!D:D),$M$1,Donnees_SIG!J3473)) -> 7.9143 | P3473: MURAMVYA
A3474: Point (783044.42368592112325132 9636335.76288937963545322) | B3474: 04e00000000000057da7 | C3474: 35.800999 | D3474: Habitation | E3474: 783044.42 | F3474: 9636335.8 | G3474: =IF(C3474="","",VLOOKUP(C3474,Classes_detaillees!B:D,Classes_detaillees!C$1,TRUE)) -> 40 | H3474: =IF(C3474="","",VLOOKUP(C3474,Classes_finales!B:D,Classes_finales!C$1,TRUE)) -> 40 | I3474: =IF(E3474="","",20) -> 20 | J3474: =Classes_finales!$W$30*C3474^3+Classes_finales!$W$31*C3474^2+Classes_finales!$W$32*C3474+Classes_finales!$W$33 -> 3.4614111 | K3474: =IF(OR(C3474<10,C3474>450),0,IF(H3474>=MAX(Classes_finales!D:D),$M$1,Donnees_SIG!J3474)) -> 3.4614111 | P3474: MURAMVYA
A3475: Point (790233.39389746799133718 9638974.14896587282419205) | B3475: 04e0000000000006f49d | C3475: 165.29939 | D3475: Habitation | E3475: 790233.39 | F3475: 9638974.1 | G3475: =IF(C3475="","",VLOOKUP(C3475,Classes_detaillees!B:D,Classes_detaillees!C$1,TRUE)) -> 170 | H3475: =IF(C3475="","",VLOOKUP(C3475,Classes_finales!B:D,Classes_finales!C$1,TRUE)) -> 80 | I3475: =IF(E3475="","",20) -> 20 | J3475: =Classes_finales!$W$30*C3475^3+Classes_finales!$W$31*C3475^2+Classes_finales!$W$32*C3475+Classes_finales!$W$33 -> -21.292054 | K3475: =IF(OR(C3475<10,C3475>450),0,IF(H3475>=MAX(Classes_finales!D:D),$M$1,Donnees_SIG!J3475)) -> 7.9143 | P3475: MURAMVYA
A3476: Point (792653.49445360968820751 9638517.07734180241823196) | B3476: 04e0000000000008f351 | C3476: 114.5936 | D3476: Habitation | E3476: 792653.49 | F3476: 9638517.1 | G3476: =IF(C3476="","",VLOOKUP(C3476,Classes_detaillees!B:D,Classes_detaillees!C$1,TRUE)) -> 115 | H3476: =IF(C3476="","",VLOOKUP(C3476,Classes_finales!B:D,Classes_finales!C$1,TRUE)) -> 80 | I3476: =IF(E3476="","",20) -> 20 | J3476: =Classes_finales!$W$30*C3476^3+Classes_finales!$W$31*C3476^2+Classes_finales!$W$32*C3476+Classes_finales!$W$33 -> 4.8362415 | K3476: =IF(OR(C3476<10,C3476>450),0,IF(H3476>=MAX(Classes_finales!D:D),$M$1,Donnees_SIG!J3476)) -> 7.9143 | P3476: MURAMVYA
...

Sheet Classes_detaillees
B1: 1 | C1: 2 | D1: 3 | E1: 4 | F1: 5 | G1: 6
B2: Surface min | C2: Surface Max. | D2: Classe | E2: Nb de toît | F2: Nombre de personnes max | G2: Nombre de personnes min | J2: solveur
B3: 0 | C3: 5 | D3: =C3 -> 5 | E3: =COUNTIF(Donnees_SIG!G:G,Classes_detaillees!D3) -> 2 | F3: =IF(C3/$K$27>=$K$29,$K$29,ROUNDDOWN(C3/$K$27,0)) -> 0 | G3: =IF(B3/$K$27>=$K$29,$K$29,ROUNDDOWN(B3/$K$27,0)) -> 0 | J3: bureau fait 405 m²
B4: =C3 -> 5 | C4: 10 | D4: =C4 -> 10 | E4: =COUNTIF(Donnees_SIG!G:G,Classes_detaillees!D4) -> 83 | F4: =IF(C4/$K$27>=$K$29,$K$29,ROUNDDOWN(C4/$K$27,0)) -> 1 | G4: =IF(B4/$K$27>=$K$29,$K$29,ROUNDDOWN(B4/$K$27,0)) -> 0
B5: =C4 -> 10 | C5: 15 | D5: =C5 -> 15 | E5: =COUNTIF(Donnees_SIG!G:G,Classes_detaillees!D5) -> 207 | F5: =IF(C5/$K$27>=$K$29,$K$29,ROUNDDOWN(C5/$K$27,0)) -> 2 | G5: =IF(B5/$K$27>=$K$29,$K$29,ROUNDDOWN(B5/$K$27,0)) -> 1
B6: =C5 -> 15 | C6: 20 | D6: =C6 -> 20 | E6: =COUNTIF(Donnees_SIG!G:G,Classes_detaillees!D6) -> 216 | F6: =IF(C6/$K$27>=$K$29,$K$29,ROUNDDOWN(C6/$K$27,0)) -> 3 | G6: =IF(B6/$K$27>=$K$29,$K$29,ROUNDDOWN(B6/$K$27,0)) -> 2
B7: =C6 -> 20 | C7: 25 | D7: =C7 -> 25 | E7: =COUNTIF(Donnees_SIG!G:G,Classes_detaillees!D7) -> 230 | F7: =IF(C7/$K$27>=$K$29,$K$29,ROUNDDOWN(C7/$K$27,0)) -> 3 | G7: =IF(B7/$K$27>=$K$29,$K$29,ROUNDDOWN(B7/$K$27,0)) -> 3
B8: =C7 -> 25 | C8: 30 | D8: =C8 -> 30 | E8: =COUNTIF(Donnees_SIG!G:G,Classes_detaillees!D8) -> 225 | F8: =IF(C8/$K$27>=$K$29,$K$29,ROUNDDOWN(C8/$K$27,0)) -> 4 | G8: =IF(B8/$K$27>=$K$29,$K$29,ROUNDDOWN(B8/$K$27,0)) -> 3
B9: =C8 -> 30 | C9: 35 | D9: =C9 -> 35 | E9: =COUNTIF(Donnees_SIG!G:G,Classes_detaillees!D9) -> 219 | F9: =IF(C9/$K$27>=$K$29,$K$29,ROUNDDOWN(C9/$K$27,0)) -> 5 | G9: =IF(B9/$K$27>=$K$29,$K$29,ROUNDDOWN(B9/$K$27,0)) -> 4
B10: =C9 -> 35 | C10: 40 | D10: =C10 -> 40 | E10: =COUNTIF(Donnees_SIG!G:G,Classes_detaillees!D10) -> 242 | F10: =IF(C10/$K$27>=$K$29,$K$29,ROUNDDOWN(C10/$K$27,0)) -> 6 | G10: =IF(B10/$K$27>=$K$29,$K$29,ROUNDDOWN(B10/$K$27,0)) -> 5
B11: =C10 -> 40 | C11: 45 | D11: =C11 -> 45 | E11: =COUNTIF(Donnees_SIG!G:G,Classes_detaillees!D11) -> 236 | F11: =IF(C11/$K$27>=$K$29,$K$29,ROUNDDOWN(C11/$K$27,0)) -> 6 | G11: =IF(B11/$K$27>=$K$29,$K$29,ROUNDDOWN(B11/$K$27,0)) -> 6
B12: =C11 -> 45 | C12: 50 | D12: =C12 -> 50 | E12: =COUNTIF(Donnees_SIG!G:G,Classes_detaillees!D12) -> 235 | F12: =IF(C12/$K$27>=$K$29,$K$29,ROUNDDOWN(C12/$K$27,0)) -> 7 | G12: =IF(B12/$K$27>=$K$29,$K$29,ROUNDDOWN(B12/$K$27,0)) -> 6
B13: =C12 -> 50 | C13: 55 | D13: =C13 -> 55 | E13: =COUNTIF(Donnees_SIG!G:G,Classes_detaillees!D13) -> 247 | F13: =IF(C13/$K$27>=$K$29,$K$29,ROUNDDOWN(C13/$K$27,0)) -> 8 | G13: =IF(B13/$K$27>=$K$29,$K$29,ROUNDDOWN(B13/$K$27,0)) -> 7
B14: =C13 -> 55 | C14: 60 | D14: =C14 -> 60 | E14: =COUNTIF(Donnees_SIG!G:G,Classes_detaillees!D14) -> 287 | F14: =IF(C14/$K$27>=$K$29,$K$29,ROUNDDOWN(C14/$K$27,0)) -> 9 | G14: =IF(B14/$K$27>=$K$29,$K$29,ROUNDDOWN(B14/$K$27,0)) -> 8
B15: =C14 -> 60 | C15: 65 | D15: =C15 -> 65 | E15: =COUNTIF(Donnees_SIG!G:G,Classes_detaillees!D15) -> 242 | F15: =IF(C15/$K$27>=$K$29,$K$29,ROUNDDOWN(C15/$K$27,0)) -> 10 | G15: =IF(B15/$K$27>=$K$29,$K$29,ROUNDDOWN(B15/$K$27,0)) -> 9
B16: =C15 -> 65 | C16: 70 | D16: =C16 -> 70 | E16: =COUNTIF(Donnees_SIG!G:G,Classes_detaillees!D16) -> 223 | F16: =IF(C16/$K$27>=$K$29,$K$29,ROUNDDOWN(C16/$K$27,0)) -> 10 | G16: =IF(B16/$K$27>=$K$29,$K$29,ROUNDDOWN(B16/$K$27,0)) -> 10
B17: =C16 -> 70 | C17: 75 | D17: =C17 -> 75 | E17: =COUNTIF(Donnees_SIG!G:G,Classes_detaillees!D17) -> 232 | F17: =IF(C17/$K$27>=$K$29,$K$29,ROUNDDOWN(C17/$K$27,0)) -> 10 | G17: =IF(B17/$K$27>=$K$29,$K$29,ROUNDDOWN(B17/$K$27,0)) -> 10 | J17: =30/2 -> 15
B18: =C17 -> 75 | C18: 80 | D18: =C18 -> 80 | E18: =COUNTIF(Donnees_SIG!G:G,Classes_detaillees!D18) -> 211 | F18: =IF(C18/$K$27>=$K$29,$K$29,ROUNDDOWN(C18/$K$27,0)) -> 10 | G18: =IF(B18/$K$27>=$K$29,$K$29,ROUNDDOWN(B18/$K$27,0)) -> 10
B19: =C18 -> 80 | C19: 85 | D19: =C19 -> 85 | E19: =COUNTIF(Donnees_SIG!G:G,Classes_detaillees!D19) -> 207 | F19: =IF(C19/$K$27>=$K$29,$K$29,ROUNDDOWN(C19/$K$27,0)) -> 10 | G19: =IF(B19/$K$27>=$K$29,$K$29,ROUNDDOWN(B19/$K$27,0)) -> 10
B20: =C19 -> 85 | C20: 90 | D20: =C20 -> 90 | E20: =COUNTIF(Donnees_SIG!G:G,Classes_detaillees!D20) -> 174 | F20: =IF(C20/$K$27>=$K$29,$K$29,ROUNDDOWN(C20/$K$27,0)) -> 10 | G20: =IF(B20/$K$27>=$K$29,$K$29,ROUNDDOWN(B20/$K$27,0)) -> 10
B21: =C20 -> 90 | C21: 95 | D21: =C21 -> 95 | E21: =COUNTIF(Donnees_SIG!G:G,Classes_detaillees!D21) -> 172 | F21: =IF(C21/$K$27>=$K$29,$K$29,ROUNDDOWN(C21/$K$27,0)) -> 10 | G21: =IF(B21/$K$27>=$K$29,$K$29,ROUNDDOWN(B21/$K$27,0)) -> 10
B22: =C21 -> 95 | C22: 100 | D22: =C22 -> 100 | E22: =COUNTIF(Donnees_SIG!G:G,Classes_detaillees!D22) -> 138 | F22: =IF(C22/$K$27>=$K$29,$K$29,ROUNDDOWN(C22/$K$27,0)) -> 10 | G22: =IF(B22/$K$27>=$K$29,$K$29,ROUNDDOWN(B22/$K$27,0)) -> 10 | J22: Moyenne d'hab/ménage | K22: 5
B23: =C22 -> 100 | C23: 105 | D23: =C23 -> 105 | E23: =COUNTIF(Donnees_SIG!G:G,Classes_detaillees!D23) -> 140 | F23: =IF(C23/$K$27>=$K$29,$K$29,ROUNDDOWN(C23/$K$27,0)) -> 10 | G23: =IF(B23/$K$27>=$K$29,$K$29,ROUNDDOWN(B23/$K$27,0)) -> 10 | J23: surface min | K23: 15
B24: =C23 -> 105 | C24: 110 | D24: =C24 -> 110 | E24: =COUNTIF(Donnees_SIG!G:G,Classes_detaillees!D24) -> 101 | F24: =IF(C24/$K$27>=$K$29,$K$29,ROUNDDOWN(C24/$K$27,0)) -> 10 | G24: =IF(B24/$K$27>=$K$29,$K$29,ROUNDDOWN(B24/$K$27,0)) -> 10 | J24: surface max | K24: 30
B25: =C24 -> 110 | C25: 115 | D25: =C25 -> 115 | E25: =COUNTIF(Donnees_SIG!G:G,Classes_detaillees!D25) -> 113 | F25: =IF(C25/$K$27>=$K$29,$K$29,ROUNDDOWN(C25/$K$27,0)) -> 10 | G25: =IF(B25/$K$27>=$K$29,$K$29,ROUNDDOWN(B25/$K$27,0)) -> 10 | J25: espace vitale min | K25: =K23/K22 -> 3
B26: =C25 -> 115 | C26: 120 | D26: =C26 -> 120 | E26: =COUNTIF(Donnees_SIG!G:G,Classes_detaillees!D26) -> 105 | F26: =IF(C26/$K$27>=$K$29,$K$29,ROUNDDOWN(C26/$K$27,0)) -> 10 | G26: =IF(B26/$K$27>=$K$29,$K$29,ROUNDDOWN(B26/$K$27,0)) -> 10 | J26: espace vitale max | K26: =K24/K22 -> 6
B27: =C26 -> 120 | C27: 125 | D27: =C27 -> 125 | E27: =COUNTIF(Donnees_SIG!G:G,Classes_detaillees!D27) -> 84 | F27: =IF(C27/$K$27>=$K$29,$K$29,ROUNDDOWN(C27/$K$27,0)) -> 10 | G27: =IF(B27/$K$27>=$K$29,$K$29,ROUNDDOWN(B27/$K$27,0)) -> 10 | J27: espace vitale moy | K27: =MEDIAN(K25:K26)+2 -> 6.5 | L27: m²/pers
B28: =C27 -> 125 | C28: 130 | D28: =C28 -> 130 | E28: =COUNTIF(Donnees_SIG!G:G,Classes_detaillees!D28) -> 89 | F28: =IF(C28/$K$27>=$K$29,$K$29,ROUNDDOWN(C28/$K$27,0)) -> 10 | G28: =IF(B28/$K$27>=$K$29,$K$29,ROUNDDOWN(B28/$K$27,0)) -> 10
B29: =C28 -> 130 | C29: 135 | D29: =C29 -> 135 | E29: =COUNTIF(Donnees_SIG!G:G,Classes_detaillees!D29) -> 84 | F29: =IF(C29/$K$27>=$K$29,$K$29,ROUNDDOWN(C29/$K$27,0)) -> 10 | G29: =IF(B29/$K$27>=$K$29,$K$29,ROUNDDOWN(B29/$K$27,0)) -> 10 | J29: Nombre max d'hab/ménage | K29: =K22*2 -> 10
B30: =C29 -> 135 | C30: 140 | D30: =C30 -> 140 | E30: =COUNTIF(Donnees_SIG!G:G,Classes_detaillees!D30) -> 89 | F30: =IF(C30/$K$27>=$K$29,$K$29,ROUNDDOWN(C30/$K$27,0)) -> 10 | G30: =IF(B30/$K$27>=$K$29,$K$29,ROUNDDOWN(B30/$K$27,0)) -> 10
B31: =C30 -> 140 | C31: 145 | D31: =C31 -> 145 | E31: =COUNTIF(Donnees_SIG!G:G,Classes_detaillees!D31) -> 67 | F31: =IF(C31/$K$27>=$K$29,$K$29,ROUNDDOWN(C31/$K$27,0)) -> 10 | G31: =IF(B31/$K$27>=$K$29,$K$29,ROUNDDOWN(B31/$K$27,0)) -> 10 | J31: =Classes_finales!J17 -> 0 | K31: =Classes_finales!K17 -> 0 | L31: =Classes_finales!L17 -> 0
B32: =C31 -> 145 | C32: 150 | D32: =C32 -> 150 | E32: =COUNTIF(Donnees_SIG!G:G,Classes_detaillees!D32) -> 63 | F32: =IF(C32/$K$27>=$K$29,$K$29,ROUNDDOWN(C32/$K$27,0)) -> 10 | G32: =IF(B32/$K$27>=$K$29,$K$29,ROUNDDOWN(B32/$K$27,0)) -> 10
B33: =C32 -> 150 | C33: 155 | D33: =C33 -> 155 | E33: =COUNTIF(Donnees_SIG!G:G,Classes_detaillees!D33) -> 54 | F33: =IF(C33/$K$27>=$K$29,$K$29,ROUNDDOWN(C33/$K$27,0)) -> 10 | G33: =IF(B33/$K$27>=$K$29,$K$29,ROUNDDOWN(B33/$K$27,0)) -> 10
B34: =C33 -> 155 | C34: 160 | D34: =C34 -> 160 | E34: =COUNTIF(Donnees_SIG!G:G,Classes_detaillees!D34) -> 50 | F34: =IF(C34/$K$27>=$K$29,$K$29,ROUNDDOWN(C34/$K$27,0)) -> 10 | G34: =IF(B34/$K$27>=$K$29,$K$29,ROUNDDOWN(B34/$K$27,0)) -> 10
B35: =C34 -> 160 | C35: 165 | D35: =C35 -> 165 | E35: =COUNTIF(Donnees_SIG!G:G,Classes_detaillees!D35) -> 33 | F35: =IF(C35/$K$27>=$K$29,$K$29,ROUNDDOWN(C35/$K$27,0)) -> 10 | G35: =IF(B35/$K$27>=$K$29,$K$29,ROUNDDOWN(B35/$K$27,0)) -> 10
B36: =C35 -> 165 | C36: 170 | D36: =C36 -> 170 | E36: =COUNTIF(Donnees_SIG!G:G,Classes_detaillees!D36) -> 39 | F36: =IF(C36/$K$27>=$K$29,$K$29,ROUNDDOWN(C36/$K$27,0)) -> 10 | G36: =IF(B36/$K$27>=$K$29,$K$29,ROUNDDOWN(B36/$K$27,0)) -> 10
B37: =C36 -> 170 | C37: 175 | D37: =C37 -> 175 | E37: =COUNTIF(Donnees_SIG!G:G,Classes_detaillees!D37) -> 36 | F37: =IF(C37/$K$27>=$K$29,$K$29,ROUNDDOWN(C37/$K$27,0)) -> 10 | G37: =IF(B37/$K$27>=$K$29,$K$29,ROUNDDOWN(B37/$K$27,0)) -> 10
B38: =C37 -> 175 | C38: 180 | D38: =C38 -> 180 | E38: =COUNTIF(Donnees_SIG!G:G,Classes_detaillees!D38) -> 34 | F38: =IF(C38/$K$27>=$K$29,$K$29,ROUNDDOWN(C38/$K$27,0)) -> 10 | G38: =IF(B38/$K$27>=$K$29,$K$29,ROUNDDOWN(B38/$K$27,0)) -> 10
B39: =C38 -> 180 | C39: 185 | D39: =C39 -> 185 | E39: =COUNTIF(Donnees_SIG!G:G,Classes_detaillees!D39) -> 25 | F39: =IF(C39/$K$27>=$K$29,$K$29,ROUNDDOWN(C39/$K$27,0)) -> 10 | G39: =IF(B39/$K$27>=$K$29,$K$29,ROUNDDOWN(B39/$K$27,0)) -> 10
B40: =C39 -> 185 | C40: 190 | D40: =C40 -> 190 | E40: =COUNTIF(Donnees_SIG!G:G,Classes_detaillees!D40) -> 29 | F40: =IF(C40/$K$27>=$K$29,$K$29,ROUNDDOWN(C40/$K$27,0)) -> 10 | G40: =IF(B40/$K$27>=$K$29,$K$29,ROUNDDOWN(B40/$K$27,0)) -> 10
...

Sheet Classes_finales
B1: =COLUMN()-1 -> 1 | C1: =COLUMN()-1 -> 2 | D1: =COLUMN()-1 -> 3 | E1: =COLUMN()-1 -> 4 | F1: =COLUMN()-1 -> 5 | G1: =COLUMN()-1 -> 6 | H1: 7 | U1: Seuils
B2: Surface min | C2: Surface Max. | D2: Classe | E2: valeur min | F2: valeur max | G2: valeur mediane | H2: Valeur de Solveur | K2: Sloveur | N2: x̄ d'habitants réels
B3: 0 | C3: 5 | D3: =C3 -> 5 | E3: =_xlfn.IFNA(VLOOKUP(D3,Classes_detaillees!D:G,4,FALSE),"") -> 0 | F3: =_xlfn.IFNA(VLOOKUP(D3,Classes_detaillees!D:G,3,FALSE),"") -> 0 | G3: =IFERROR(AVERAGE(E3:F3),"") -> 0 | H3: 0 | K3: =$W$30*D3^3+$W$31*D3^2+$W$32*D3+$W$33 -> -0.1407
B4: =C3 -> 5 | C4: 10 | D4: =C4 -> 10 | E4: =_xlfn.IFNA(VLOOKUP(D4,Classes_detaillees!D:G,4,FALSE),"") -> 0 | F4: =_xlfn.IFNA(VLOOKUP(D4,Classes_detaillees!D:G,3,FALSE),"") -> 1 | G4: =IFERROR(AVERAGE(E4:F4),"") -> 0.5 | H4: 0 | K4: =$W$30*D4^3+$W$31*D4^2+$W$32*D4+$W$33 -> 0.2913
B5: 10 | C5: =Classes_detaillees!K23 -> 15 | D5: =C5 -> 15 | E5: =_xlfn.IFNA(VLOOKUP(D5,Classes_detaillees!D:G,4,FALSE),"") -> 1 | F5: =_xlfn.IFNA(VLOOKUP(D5,Classes_detaillees!D:G,3,FALSE),"") -> 2 | G5: =IFERROR(AVERAGE(E5:F5),"") -> 1.5 | H5: 1 | K5: =$W$30*D5^3+$W$31*D5^2+$W$32*D5+$W$33 -> 0.8033 | T5: =VLOOKUP(C6,Classes_detaillees!D:E,2,FALSE) -> 225 | U5: =T5 -> 225
B6: =C5 -> 15 | C6: =Classes_detaillees!K24 -> 30 | D6: =C6 -> 30 | E6: =_xlfn.IFNA(VLOOKUP(D6,Classes_detaillees!D:G,4,FALSE),"") -> 3 | F6: =_xlfn.IFNA(VLOOKUP(D6,Classes_detaillees!D:G,3,FALSE),"") -> 4 | G6: =IFERROR(AVERAGE(E6:F6),"") -> 3.5 | H6: 2 | K6: =$W$30*D6^3+$W$31*D6^2+$W$32*D6+$W$33 -> 2.6693 | T6: =VLOOKUP(C7,Classes_detaillees!D:E,2,FALSE) -> 219 | U6: =T6 -> 219
B7: =C6 -> 30 | C7: 35 | D7: =C7 -> 35 | E7: =_xlfn.IFNA(VLOOKUP(D7,Classes_detaillees!D:G,4,FALSE),"") -> 4 | F7: =_xlfn.IFNA(VLOOKUP(D7,Classes_detaillees!D:G,3,FALSE),"") -> 5 | G7: =IFERROR(AVERAGE(E7:F7),"") -> 4.5 | H7: 4 | K7: =$W$30*D7^3+$W$31*D7^2+$W$32*D7+$W$33 -> 3.3513 | T7: =VLOOKUP(C8,Classes_detaillees!D:E,2,FALSE) -> 242 | U7: =T7 -> 242
B8: =C7 -> 35 | C8: 40 | D8: =C8 -> 40 | E8: =_xlfn.IFNA(VLOOKUP(D8,Classes_detaillees!D:G,4,FALSE),"") -> 5 | F8: =_xlfn.IFNA(VLOOKUP(D8,Classes_detaillees!D:G,3,FALSE),"") -> 6 | G8: =IFERROR(AVERAGE(E8:F8),"") -> 5.5 | H8: 4 | K8: =$W$30*D8^3+$W$31*D8^2+$W$32*D8+$W$33 -> 4.0383 | T8: =VLOOKUP(C9,Classes_detaillees!D:E,2,FALSE) -> 235 | U8: =T8 -> 235
B9: =C8 -> 40 | C9: 50 | D9: =C9 -> 50 | E9: =_xlfn.IFNA(VLOOKUP(D9,Classes_detaillees!D:G,4,FALSE),"") -> 6 | F9: =_xlfn.IFNA(VLOOKUP(D9,Classes_detaillees!D:G,3,FALSE),"") -> 7 | G9: =IFERROR(AVERAGE(E9:F9),"") -> 6.5 | H9: 5 | K9: =$W$30*D9^3+$W$31*D9^2+$W$32*D9+$W$33 -> 5.3673 | T9: =VLOOKUP(C10,Classes_detaillees!D:E,2,FALSE) -> 287 | U9: =T9 -> 287
B10: =C9 -> 50 | C10: 60 | D10: =C10 -> 60 | E10: =_xlfn.IFNA(VLOOKUP(D10,Classes_detaillees!D:G,4,FALSE),"") -> 8 | F10: =_xlfn.IFNA(VLOOKUP(D10,Classes_detaillees!D:G,3,FALSE),"") -> 9 | G10: =IFERROR(AVERAGE(E10:F10),"") -> 8.5 | H10: 6 | K10: =$W$30*D10^3+$W$31*D10^2+$W$32*D10+$W$33 -> 6.5363 | T10: =VLOOKUP(C11,Classes_detaillees!D:E,2,FALSE) -> 223 | U10: =T10 -> 223
B11: =C10 -> 60 | C11: 70 | D11: =C11 -> 70 | E11: =_xlfn.IFNA(VLOOKUP(D11,Classes_detaillees!D:G,4,FALSE),"") -> 10 | F11: =_xlfn.IFNA(VLOOKUP(D11,Classes_detaillees!D:G,3,FALSE),"") -> 10 | G11: =IFERROR(AVERAGE(E11:F11),"") -> 10 | H11: 7 | K11: =$W$30*D11^3+$W$31*D11^2+$W$32*D11+$W$33 -> 7.4253 | T11: 0 | U11: 180
B12: =C11 -> 70 | C12: 80 | D12: =C12 -> 80 | H12: 7
N16: 34251
V30: a | W30: -2e-05 | Y30: =MAX(D:D) -> 80
V31: b | W31: 0.0022 | Y31: =W30*Y30^Z31 -> -10.24 | Z31: 3
V32: c | W32: 0.0569 | Y32: =W31*Y30^Z32 -> 14.08 | Z32: 2
V33: d | W33: -0.4777 | Y33: =W32*Y30^Z33 -> 4.552 | Z33: 1
Y34: =W33 -> -0.4777
V35: Pop modèle | W35: =SUM(Donnees_SIG!K:K) -> 33253.081
V36: Pop admin | W36: =N16 -> 34251 | Y36: =Y31+Y32+Y33+Y34 -> 7.9143
W37: =(W35-W36)/AVERAGE(W35:W36) -> -0.029566175
